Workbook

Sheet Landed cost blocks
A1: INTERNAL — not for SIAS · Landed-cost blocks with the proportional uplift · ₴ per pack
A2: Purchase + delivery + import VAT + financing = real landed cost; the uplift (assumption, cell G14 on the "Price 120 UAH" sheets) is added on top as a separate block.
A4: 33 PALLETS · FULL TRUCK
B5: Purchase pack price × rate | C5: Delivery freight, broker, terminal | D5: Import VAT 20 % on goods and freight | E5: Financing 2.5 % of the sum | F5: Real landed cost, ₴ | G5: Uplift (assumption), ₴ | H5: Landed cost with uplift, ₴ | I5: Check vs model sheet
A6: BEFORE · 4 SKUs (Vegetable, Spicy, Beef, Chicken) | B6: 33.28 | C6: 3.6684464 | D6: 7.1275274 | E6: 1.1018993 | F6: =SUM(B6:E6) -> 45.177873 | G6: =F6*'Price 120 UAH - 33 pallets'!G14 -> 5.6472341 | H6: =F6+G6 -> 50.825107 | I6: =ROUND(H6-'Price 120 UAH - 33 pallets'!C4,4) -> 0
A7: BEFORE · 2 SKUs (Gouda, Carbonara) | B7: 38.4 | C7: 4.2328228 | D7: 8.22407 | E7: 1.2714223 | F7: =SUM(B7:E7) -> 52.128315 | G7: =F7*'Price 120 UAH - 33 pallets'!G14 -> 6.5160394 | H7: =F7+G7 -> 58.644354 | I7: =ROUND(H7-'Price 120 UAH - 33 pallets'!C6,4) -> 0
A8: AFTER · SIAS request (all 6 SKUs) | B8: ='Price 120 UAH - 33 pallets'!B19*'Price 120 UAH - 33 pallets'!F14 -> 27.648 | C8: =('Price 120 UAH - 33 pallets'!E16+'Price 120 UAH - 33 pallets'!F16+'Price 120 UAH - 33 pallets'!G16)/('Price 120 UAH - 33 pallets'!C18*'Price 120 UAH - 33 pallets'!D18)*'Price 120 UAH - 33 pallets'!F14 -> 3.9078788 | D8: =('Price 120 UAH - 33 pallets'!B19+'Price 120 UAH - 33 pallets'!E16*'Price 120 UAH - 33 pallets'!B18/('Price 120 UAH - 33 pallets'!C18*'Price 120 UAH - 33 pallets'!D18))*(1+'Price 120 UAH - 33 pallets'!D16)*'Price 120 UAH - 33 pallets'!B16*'Price 120 UAH - 33 pallets'!F14 -> 6.031903 | E8: =(B8+C8+D8+('Price 120 UAH - 33 pallets'!B19+'Price 120 UAH - 33 pallets'!E16*'Price 120 UAH - 33 pallets'!B18/('Price 120 UAH - 33 pallets'!C18*'Price 120 UAH - 33 pallets'!D18))*'Price 120 UAH - 33 pallets'!D16*'Price 120 UAH - 33 pallets'!F14)*'Price 120 UAH - 33 pallets'!C16 -> 0.93969455 | F8: =SUM(B8:E8) -> 38.527476 | G8: =F8*'Price 120 UAH - 33 pallets'!G14 -> 4.8159345 | H8: =F8+G8 -> 43.343411 | I8: =ROUND(H8-'Price 120 UAH - 33 pallets'!C8,4) -> 0
A10: 6 PALLETS
B11: Purchase pack price × rate | C11: Delivery freight, broker, terminal | D11: Import VAT 20 % on goods and freight | E11: Financing 2.5 % of the sum | F11: Real landed cost, ₴ | G11: Uplift (assumption), ₴ | H11: Landed cost with uplift, ₴ | I11: Check vs model sheet
A12: BEFORE · 4 SKUs (Vegetable, Spicy, Beef, Chicken) | B12: 33.28 | C12: 14.86439 | D12: 8.5026341 | E12: 1.4161756 | F12: =SUM(B12:E12) -> 58.0632 | G12: =F12*'Price 120 UAH - 6 pallets'!G14 -> 7.2579 | H12: =F12+G12 -> 65.3211 | I12: =ROUND(H12-'Price 120 UAH - 6 pallets'!C4,4) -> 0
A13: BEFORE · 2 SKUs (Gouda, Carbonara) | B13: 38.4 | C13: 17.15122 | D13: 9.8107317 | E13: 1.6340488 | F13: =SUM(B13:E13) -> 66.996 | G13: =F13*'Price 120 UAH - 6 pallets'!G14 -> 8.3745 | H13: =F13+G13 -> 75.3705 | I13: =ROUND(H13-'Price 120 UAH - 6 pallets'!C6,4) -> 0
A14: AFTER · SIAS request (all 6 SKUs) | B14: ='Price 120 UAH - 6 pallets'!B20*'Price 120 UAH - 6 pallets'!F14 -> 16.384 | C14: =('Price 120 UAH - 6 pallets'!E16+'Price 120 UAH - 6 pallets'!F16+'Price 120 UAH - 6 pallets'!G16)/('Price 120 UAH - 6 pallets'!C18*'Price 120 UAH - 6 pallets'!D18)*'Price 120 UAH - 6 pallets'!F14 -> 15.626667 | D14: =('Price 120 UAH - 6 pallets'!B20+'Price 120 UAH - 6 pallets'!E16*'Price 120 UAH - 6 pallets'!B18/('Price 120 UAH - 6 pallets'!C18*'Price 120 UAH - 6 pallets'!D18))*(1+'Price 120 UAH - 6 pallets'!D16)*'Price 120 UAH - 6 pallets'!B16*'Price 120 UAH - 6 pallets'!F14 -> 5.2181333 | E14: =(B14+C14+D14+('Price 120 UAH - 6 pallets'!B20+'Price 120 UAH - 6 pallets'!E16*'Price 120 UAH - 6 pallets'!B18/('Price 120 UAH - 6 pallets'!C18*'Price 120 UAH - 6 pallets'!D18))*'Price 120 UAH - 6 pallets'!D16*'Price 120 UAH - 6 pallets'!F14)*'Price 120 UAH - 6 pallets'!C16 -> 0.93072 | F14: =SUM(B14:E14) -> 38.15952 | G14: =F14*'Price 120 UAH - 6 pallets'!G14 -> 4.76994 | H14: =F14+G14 -> 42.92946 | I14: =ROUND(H14-'Price 120 UAH - 6 pallets'!C8,4) -> 0

Sheet Model 6 pallets
B1: Ramen. Partner price and shelf price — 6 pallets
B2: Delivery scenario | D2: 6 pallets | E2: Landed cost = Self-Cost_Sias (col. AL) × (1 + uplift from G14 on the "Price 120 UAH" sheet). Cost composition preserved.
B3: Rate, UAH/EUR | D3: 51.2 | E3: Rate 51.20 UAH/EUR — from Self-Cost_Sias.
B4: Chain bonus, % | D4: 0.35 | E4: ="Chain bonus "&ROUND(D4*100,0)&"%; shelf = partner price × "&D6&"." -> Chain bonus 35%; shelf = partner price × 1.4.
B5: Target margin, % | D5: ='Price 120 UAH - 6 pallets'!C14 -> 0.14375 | E5: =ROUND(D5*100,0)&"% = (partner price − landed cost − bonus) / full partner price." -> 14% = (partner price − landed cost − bonus) / full partner price.
B6: Chain markup (x) | D6: 1.4 | E6: Profit after bonus = partner price − landed cost − chain bonus.
B7: Partner price | D7: incl. VAT | E7: VAT as in the example: landed cost kept in full; the price already includes VAT. No multiplication by 1.20.
B8: Share of price for landed cost | D8: =IF(AND(COUNT(D3:D6)=4,D3>0,D4>=0,D5>=0,D4+D5<1,D6>0),1-D4-D5,NA()) -> 0.50625 | E8: ="100% − bonus − margin. Current terms: 100% − "&ROUND(D4*100,0)&"% − "&ROUND(D5*100,0)&"% = "&ROUND(D8*100,0)&"%." -> 100% − bonus − margin. Current terms: 100% − 35% − 14% = 51%.
A9: PRODUCT | E9: LANDED COST | G9: PARTNER PRICE AND PROFIT | K9: SHELF | L9: MODEL: ZERO MARGIN | N9: PROFIT PER PACK | P9: 0.3 | U9: 0.25 | Z9: 0.2 | AE9: 0.15
A10: № | B10: Group | C10: Item | D10: Weight, g | E10: Landed cost incl. uplift, EUR/pack | F10: 1. Landed cost, UAH/pack | G10: 2. Partner price incl. VAT | H10: 3. Chain bonus, UAH | I10: 4. Profit after bonus, UAH | J10: 5. Margin per example | K10: 6. Shelf price incl. VAT, UAH | L10: Min. partner price | M10: Min. shelf price | N10: Gross profit per example, before bonus, UAH/pack | O10: Profit after bonus per example, UAH/pack | P10: Partner price incl. VAT, UAH | Q10: Chain bonus, UAH | R10: Profit after bonus, UAH | S10: Margin check | T10: Shelf price incl. VAT, UAH | U10: Partner price incl. VAT, UAH | V10: Chain bonus, UAH | W10: Profit after bonus, UAH | X10: Margin check | Y10: Shelf price incl. VAT, UAH | Z10: Partner price incl. VAT, UAH | AA10: Chain bonus, UAH | AB10: Profit after bonus, UAH | AC10: Margin check | AD10: Shelf price incl. VAT, UAH | AE10: Partner price incl. VAT, UAH | AF10: Chain bonus, UAH | AG10: Profit after bonus, UAH | AH10: Margin check | AI10: Shelf price incl. VAT, UAH | AL10: Self-Cost source, EUR/pack (before uplift)
A11: 1 | B11: SIAS — pack ramen | C11: Gouda Cheese 123 g | D11: 123 | E11: =AL11*(1+'Price 120 UAH - 6 pallets'!$G$14) -> 1.4720801 | F11: =IF(AND(ISNUMBER(E11),ISNUMBER($D$8)),E11*$D$3,NA()) -> 75.3705 | G11: =F11/$D$8 -> 148.88 | H11: =G11*$D$4 -> 52.108 | I11: =G11-F11-H11 -> 21.4015 | J11: =I11/G11 -> 0.14375 | K11: =G11*$D$6 -> 208.432 | L11: =F11/(1-$D$4) -> 115.95462 | M11: =L11*$D$6 -> 162.33646 | N11: =G11-F11 -> 73.5095 | O11: =N11-H11 -> 21.4015 | P11: =$F11/(1-$D$4-$P$9) -> 215.34429 | Q11: =P11*$D$4 -> 75.3705 | R11: =P11-$F11-Q11 -> 64.603286 | S11: =R11/P11 -> 0.3 | T11: =P11*$D$6 -> 301.482 | U11: =$F11/(1-$D$4-$U$9) -> 188.42625 | V11: =U11*$D$4 -> 65.949187 | W11: =U11-$F11-V11 -> 47.106563 | X11: =W11/U11 -> 0.25 | Y11: =U11*$D$6 -> 263.79675 | Z11: =$F11/(1-$D$4-$Z$9) -> 167.49 | AA11: =Z11*$D$4 -> 58.6215 | AB11: =Z11-$F11-AA11 -> 33.498 | AC11: =AB11/Z11 -> 0.2 | AD11: =Z11*$D$6 -> 234.486 | AE11: =$F11/(1-$D$4-$AE$9) -> 150.741 | AF11: =AE11*$D$4 -> 52.75935 | AG11: =AE11-$F11-AF11 -> 22.61115 | AH11: =AG11/AE11 -> 0.15 | AI11: =AE11*$D$6 -> 211.0374 | AL11: 1.3085156
A12: 2 | B12: SIAS — pack ramen | C12: Carbonara Spicy 131 g | D12: 131 | E12: =AL12*(1+'Price 120 UAH - 6 pallets'!$G$14) -> 1.4720801 | F12: =IF(AND(ISNUMBER(E12),ISNUMBER($D$8)),E12*$D$3,NA()) -> 75.3705 | G12: =F12/$D$8 -> 148.88 | H12: =G12*$D$4 -> 52.108 | I12: =G12-F12-H12 -> 21.4015 | J12: =I12/G12 -> 0.14375 | K12: =G12*$D$6 -> 208.432 | L12: =F12/(1-$D$4) -> 115.95462 | M12: =L12*$D$6 -> 162.33646 | N12: =G12-F12 -> 73.5095 | O12: =N12-H12 -> 21.4015 | P12: =$F12/(1-$D$4-$P$9) -> 215.34429 | Q12: =P12*$D$4 -> 75.3705 | R12: =P12-$F12-Q12 -> 64.603286 | S12: =R12/P12 -> 0.3 | T12: =P12*$D$6 -> 301.482 | U12: =$F12/(1-$D$4-$U$9) -> 188.42625 | V12: =U12*$D$4 -> 65.949187 | W12: =U12-$F12-V12 -> 47.106563 | X12: =W12/U12 -> 0.25 | Y12: =U12*$D$6 -> 263.79675 | Z12: =$F12/(1-$D$4-$Z$9) -> 167.49 | AA12: =Z12*$D$4 -> 58.6215 | AB12: =Z12-$F12-AA12 -> 33.498 | AC12: =AB12/Z12 -> 0.2 | AD12: =Z12*$D$6 -> 234.486 | AE12: =$F12/(1-$D$4-$AE$9) -> 150.741 | AF12: =AE12*$D$4 -> 52.75935 | AG12: =AE12-$F12-AF12 -> 22.61115 | AH12: =AG12/AE12 -> 0.15 | AI12: =AE12*$D$6 -> 211.0374 | AL12: 1.3085156
A13: 3 | B13: SIAS — pack ramen | C13: Vegetable Flavor 113 g | D13: 113 | E13: =AL13*(1+'Price 120 UAH - 6 pallets'!$G$14) -> 1.2758027 | F13: =IF(AND(ISNUMBER(E13),ISNUMBER($D$8)),E13*$D$3,NA()) -> 65.3211 | G13: =F13/$D$8 -> 129.02933 | H13: =G13*$D$4 -> 45.160267 | I13: =G13-F13-H13 -> 18.547967 | J13: =I13/G13 -> 0.14375 | K13: =G13*$D$6 -> 180.64107 | L13: =F13/(1-$D$4) -> 100.494 | M13: =L13*$D$6 -> 140.6916 | N13: =G13-F13 -> 63.708233 | O13: =N13-H13 -> 18.547967 | P13: =$F13/(1-$D$4-$P$9) -> 186.63171 | Q13: =P13*$D$4 -> 65.3211 | R13: =P13-$F13-Q13 -> 55.989514 | S13: =R13/P13 -> 0.3 | T13: =P13*$D$6 -> 261.2844 | U13: =$F13/(1-$D$4-$U$9) -> 163.30275 | V13: =U13*$D$4 -> 57.155962 | W13: =U13-$F13-V13 -> 40.825687 | X13: =W13/U13 -> 0.25 | Y13: =U13*$D$6 -> 228.62385 | Z13: =$F13/(1-$D$4-$Z$9) -> 145.158 | AA13: =Z13*$D$4 -> 50.8053 | AB13: =Z13-$F13-AA13 -> 29.0316 | AC13: =AB13/Z13 -> 0.2 | AD13: =Z13*$D$6 -> 203.2212 | AE13: =$F13/(1-$D$4-$AE$9) -> 130.6422 | AF13: =AE13*$D$4 -> 45.72477 | AG13: =AE13-$F13-AF13 -> 19.59633 | AH13: =AG13/AE13 -> 0.15 | AI13: =AE13*$D$6 -> 182.89908 | AL13: 1.1340469
A14: 4 | B14: SIAS — pack ramen | C14: Spicy Flavor 112.5 g | D14: 112.5 | E14: =AL14*(1+'Price 120 UAH - 6 pallets'!$G$14) -> 1.2758027 | F14: =IF(AND(ISNUMBER(E14),ISNUMBER($D$8)),E14*$D$3,NA()) -> 65.3211 | G14: =F14/$D$8 -> 129.02933 | H14: =G14*$D$4 -> 45.160267 | I14: =G14-F14-H14 -> 18.547967 | J14: =I14/G14 -> 0.14375 | K14: =G14*$D$6 -> 180.64107 | L14: =F14/(1-$D$4) -> 100.494 | M14: =L14*$D$6 -> 140.6916 | N14: =G14-F14 -> 63.708233 | O14: =N14-H14 -> 18.547967 | P14: =$F14/(1-$D$4-$P$9) -> 186.63171 | Q14: =P14*$D$4 -> 65.3211 | R14: =P14-$F14-Q14 -> 55.989514 | S14: =R14/P14 -> 0.3 | T14: =P14*$D$6 -> 261.2844 | U14: =$F14/(1-$D$4-$U$9) -> 163.30275 | V14: =U14*$D$4 -> 57.155962 | W14: =U14-$F14-V14 -> 40.825687 | X14: =W14/U14 -> 0.25 | Y14: =U14*$D$6 -> 228.62385 | Z14: =$F14/(1-$D$4-$Z$9) -> 145.158 | AA14: =Z14*$D$4 -> 50.8053 | AB14: =Z14-$F14-AA14 -> 29.0316 | AC14: =AB14/Z14 -> 0.2 | AD14: =Z14*$D$6 -> 203.2212 | AE14: =$F14/(1-$D$4-$AE$9) -> 130.6422 | AF14: =AE14*$D$4 -> 45.72477 | AG14: =AE14-$F14-AF14 -> 19.59633 | AH14: =AG14/AE14 -> 0.15 | AI14: =AE14*$D$6 -> 182.89908 | AL14: 1.1340469
A15: 5 | B15: SIAS — pack ramen | C15: Beef Flavor 113 g | D15: 113 | E15: =AL15*(1+'Price 120 UAH - 6 pallets'!$G$14) -> 1.2758027 | F15: =IF(AND(ISNUMBER(E15),ISNUMBER($D$8)),E15*$D$3,NA()) -> 65.3211 | G15: =F15/$D$8 -> 129.02933 | H15: =G15*$D$4 -> 45.160267 | I15: =G15-F15-H15 -> 18.547967 | J15: =I15/G15 -> 0.14375 | K15: =G15*$D$6 -> 180.64107 | L15: =F15/(1-$D$4) -> 100.494 | M15: =L15*$D$6 -> 140.6916 | N15: =G15-F15 -> 63.708233 | O15: =N15-H15 -> 18.547967 | P15: =$F15/(1-$D$4-$P$9) -> 186.63171 | Q15: =P15*$D$4 -> 65.3211 | R15: =P15-$F15-Q15 -> 55.989514 | S15: =R15/P15 -> 0.3 | T15: =P15*$D$6 -> 261.2844 | U15: =$F15/(1-$D$4-$U$9) -> 163.30275 | V15: =U15*$D$4 -> 57.155962 | W15: =U15-$F15-V15 -> 40.825687 | X15: =W15/U15 -> 0.25 | Y15: =U15*$D$6 -> 228.62385 | Z15: =$F15/(1-$D$4-$Z$9) -> 145.158 | AA15: =Z15*$D$4 -> 50.8053 | AB15: =Z15-$F15-AA15 -> 29.0316 | AC15: =AB15/Z15 -> 0.2 | AD15: =Z15*$D$6 -> 203.2212 | AE15: =$F15/(1-$D$4-$AE$9) -> 130.6422 | AF15: =AE15*$D$4 -> 45.72477 | AG15: =AE15-$F15-AF15 -> 19.59633 | AH15: =AG15/AE15 -> 0.15 | AI15: =AE15*$D$6 -> 182.89908 | AL15: 1.1340469
A16: 6 | B16: SIAS — pack ramen | C16: Chicken Flavor 113 g | D16: 113 | E16: =AL16*(1+'Price 120 UAH - 6 pallets'!$G$14) -> 1.2758027 | F16: =IF(AND(ISNUMBER(E16),ISNUMBER($D$8)),E16*$D$3,NA()) -> 65.3211 | G16: =F16/$D$8 -> 129.02933 | H16: =G16*$D$4 -> 45.160267 | I16: =G16-F16-H16 -> 18.547967 | J16: =I16/G16 -> 0.14375 | K16: =G16*$D$6 -> 180.64107 | L16: =F16/(1-$D$4) -> 100.494 | M16: =L16*$D$6 -> 140.6916 | N16: =G16-F16 -> 63.708233 | O16: =N16-H16 -> 18.547967 | P16: =$F16/(1-$D$4-$P$9) -> 186.63171 | Q16: =P16*$D$4 -> 65.3211 | R16: =P16-$F16-Q16 -> 55.989514 | S16: =R16/P16 -> 0.3 | T16: =P16*$D$6 -> 261.2844 | U16: =$F16/(1-$D$4-$U$9) -> 163.30275 | V16: =U16*$D$4 -> 57.155962 | W16: =U16-$F16-V16 -> 40.825687 | X16: =W16/U16 -> 0.25 | Y16: =U16*$D$6 -> 228.62385 | Z16: =$F16/(1-$D$4-$Z$9) -> 145.158 | AA16: =Z16*$D$4 -> 50.8053 | AB16: =Z16-$F16-AA16 -> 29.0316 | AC16: =AB16/Z16 -> 0.2 | AD16: =Z16*$D$6 -> 203.2212 | AE16: =$F16/(1-$D$4-$AE$9) -> 130.6422 | AF16: =AE16*$D$4 -> 45.72477 | AG16: =AE16-$F16-AF16 -> 19.59633 | AH16: =AG16/AE16 -> 0.15 | AI16: =AE16*$D$6 -> 182.89908 | AL16: 1.1340469
B19: Each step of price formation — per your example
A21: № | B21: What we calculate | D21: Action | F21: =C11 -> Gouda Cheese 123 g | G21: =C12 -> Carbonara Spicy 131 g | H21: =C13 -> Vegetable Flavor 113 g | I21: =C14 -> Spicy Flavor 112.5 g | J21: =C15 -> Beef Flavor 113 g | K21: =C16 -> Chicken Flavor 113 g
A22: 1 | B22: Landed cost in Ukraine, EUR/pack | D22: From Self-Cost | F22: =E11 -> 1.4720801 | G22: =E12 -> 1.4720801 | H22: =E13 -> 1.2758027 | I22: =E14 -> 1.2758027 | J22: =E15 -> 1.2758027 | K22: =E16 -> 1.2758027
A23: 2 | B23: Rate, UAH/EUR | D23: Input in D3 | F23: =$D$3 -> 51.2 | G23: =$D$3 -> 51.2 | H23: =$D$3 -> 51.2 | I23: =$D$3 -> 51.2 | J23: =$D$3 -> 51.2 | K23: =$D$3 -> 51.2
A24: 3 | B24: Landed cost in Ukraine, UAH/pack | D24: Step 1 × step 2 | F24: =F11 -> 75.3705 | G24: =F12 -> 75.3705 | H24: =F13 -> 65.3211 | I24: =F14 -> 65.3211 | J24: =F15 -> 65.3211 | K24: =F16 -> 65.3211
A25: 4 | B25: Full partner price, % | D25: Base for all percentages | F25: 1 | G25: 1 | H25: 1 | I25: 1 | J25: 1 | K25: 1
A26: 5 | B26: Chain bonus, % | D26: Input in D4 | F26: =$D$4 -> 0.35 | G26: =$D$4 -> 0.35 | H26: =$D$4 -> 0.35 | I26: =$D$4 -> 0.35 | J26: =$D$4 -> 0.35 | K26: =$D$4 -> 0.35
A27: 6 | B27: Share of price after bonus, % | D27: Step 4 − step 5 | F27: =1-$D$4 -> 0.65 | G27: =1-$D$4 -> 0.65 | H27: =1-$D$4 -> 0.65 | I27: =1-$D$4 -> 0.65 | J27: =1-$D$4 -> 0.65 | K27: =1-$D$4 -> 0.65
A28: 7 | B28: Our target margin, % | D28: Input in D5 | F28: =$D$5 -> 0.14375 | G28: =$D$5 -> 0.14375 | H28: =$D$5 -> 0.14375 | I28: =$D$5 -> 0.14375 | J28: =$D$5 -> 0.14375 | K28: =$D$5 -> 0.14375
A29: 8 | B29: Share of price for landed cost, % | D29: Step 6 − step 7 | F29: =$D$8 -> 0.50625 | G29: =$D$8 -> 0.50625 | H29: =$D$8 -> 0.50625 | I29: =$D$8 -> 0.50625 | J29: =$D$8 -> 0.50625 | K29: =$D$8 -> 0.50625
A30: 9 | B30: Partner price incl. VAT, UAH/pack | D30: Step 3 ÷ step 8 | F30: =G11 -> 148.88 | G30: =G12 -> 148.88 | H30: =G13 -> 129.02933 | I30: =G14 -> 129.02933 | J30: =G15 -> 129.02933 | K30: =G16 -> 129.02933
A31: 10 | B31: Gross profit before bonus, UAH/pack | D31: Step 9 − step 3 | F31: =N11 -> 73.5095 | G31: =N12 -> 73.5095 | H31: =N13 -> 63.708233 | I31: =N14 -> 63.708233 | J31: =N15 -> 63.708233 | K31: =N16 -> 63.708233
A32: 11 | B32: Chain bonus, UAH/pack | D32: Step 9 × step 5 | F32: =H11 -> 52.108 | G32: =H12 -> 52.108 | H32: =H13 -> 45.160267 | I32: =H14 -> 45.160267 | J32: =H15 -> 45.160267 | K32: =H16 -> 45.160267
A33: 12 | B33: Left for us after landed cost and bonus, UAH/pack | D33: Step 10 − step 11 | F33: =I11 -> 21.4015 | G33: =I12 -> 21.4015 | H33: =I13 -> 18.547967 | I33: =I14 -> 18.547967 | J33: =I15 -> 18.547967 | K33: =I16 -> 18.547967
A34: 13 | B34: Check of our margin after bonus, % | D34: Step 12 ÷ step 9 | F34: =J11 -> 0.14375 | G34: =J12 -> 0.14375 | H34: =J13 -> 0.14375 | I34: =J14 -> 0.14375 | J34: =J15 -> 0.14375 | K34: =J16 -> 0.14375
A35: 14 | B35: Retailer markup for shelf, % | D35: Multiplier D6 − 1 | F35: =$D$6-1 -> 0.4 | G35: =$D$6-1 -> 0.4 | H35: =$D$6-1 -> 0.4 | I35: =$D$6-1 -> 0.4 | J35: =$D$6-1 -> 0.4 | K35: =$D$6-1 -> 0.4
A36: 15 | B36: Retailer multiplier | D36: 1 + step 14 | F36: =$D$6 -> 1.4 | G36: =$D$6 -> 1.4 | H36: =$D$6 -> 1.4 | I36: =$D$6 -> 1.4 | J36: =$D$6 -> 1.4 | K36: =$D$6 -> 1.4
A37: 16 | B37: Shelf price incl. VAT, UAH/pack | D37: Step 9 × step 15 | F37: =K11 -> 208.432 | G37: =K12 -> 208.432 | H37: =K13 -> 180.64107 | I37: =K14 -> 180.64107 | J37: =K15 -> 180.64107 | K37: =K16 -> 180.64107
A38: 17 | B38: Partner price at zero profit for us, UAH/pack | D38: Step 3 ÷ step 6 | F38: =L11 -> 115.95462 | G38: =L12 -> 115.95462 | H38: =L13 -> 100.494 | I38: =L14 -> 100.494 | J38: =L15 -> 100.494 | K38: =L16 -> 100.494
A39: 18 | B39: Shelf price at zero profit for us, UAH/pack | D39: Step 17 × step 15 | F39: =M11 -> 162.33646 | G39: =M12 -> 162.33646 | H39: =M13 -> 140.6916 | I39: =M14 -> 140.6916 | J39: =M15 -> 140.6916 | K39: =M16 -> 140.6916

Sheet Model 33 pallets
B1: Ramen. Partner price and shelf price — 33 pallets / Full Truck
B2: Delivery scenario | D2: 33 pallets | E2: Landed cost = Self-Cost_Sias (col. AL) × (1 + uplift from G14 on the "Price 120 UAH" sheet). Cost composition preserved.
B3: Rate, UAH/EUR | D3: 51.2 | E3: Rate 51.20 UAH/EUR — from Self-Cost_Sias.
B4: Chain bonus, % | D4: 0.35 | E4: ="Chain bonus "&ROUND(D4*100,0)&"%; shelf = partner price × "&D6&"." -> Chain bonus 35%; shelf = partner price × 1.4.
B5: Target margin, % | D5: ='Price 120 UAH - 33 pallets'!C14 -> 0.14375 | E5: =ROUND(D5*100,0)&"% = (partner price − landed cost − bonus) / full partner price." -> 14% = (partner price − landed cost − bonus) / full partner price.
B6: Chain markup (x) | D6: 1.4 | E6: Profit after bonus = partner price − landed cost − chain bonus.
B7: Partner price | D7: incl. VAT | E7: VAT as in the example: landed cost kept in full; the price already includes VAT. No multiplication by 1.20.
B8: Share of price for landed cost | D8: =IF(AND(COUNT(D3:D6)=4,D3>0,D4>=0,D5>=0,D4+D5<1,D6>0),1-D4-D5,NA()) -> 0.50625 | E8: ="100% − bonus − margin. Current terms: 100% − "&ROUND(D4*100,0)&"% − "&ROUND(D5*100,0)&"% = "&ROUND(D8*100,0)&"%." -> 100% − bonus − margin. Current terms: 100% − 35% − 14% = 51%.
A9: PRODUCT | E9: LANDED COST | G9: PARTNER PRICE AND PROFIT | K9: SHELF | L9: MODEL: ZERO MARGIN | N9: PROFIT PER PACK | P9: 0.3 | U9: 0.25 | Z9: 0.2 | AE9: 0.15
A10: № | B10: Group | C10: Item | D10: Weight, g | E10: Landed cost incl. uplift, EUR/pack | F10: 1. Landed cost, UAH/pack | G10: 2. Partner price incl. VAT | H10: 3. Chain bonus, UAH | I10: 4. Profit after bonus, UAH | J10: 5. Margin per example | K10: 6. Shelf price incl. VAT, UAH | L10: Min. partner price | M10: Min. shelf price | N10: Gross profit per example, before bonus, UAH/pack | O10: Profit after bonus per example, UAH/pack | P10: Partner price incl. VAT, UAH | Q10: Chain bonus, UAH | R10: Profit after bonus, UAH | S10: Margin check | T10: Shelf price incl. VAT, UAH | U10: Partner price incl. VAT, UAH | V10: Chain bonus, UAH | W10: Profit after bonus, UAH | X10: Margin check | Y10: Shelf price incl. VAT, UAH | Z10: Partner price incl. VAT, UAH | AA10: Chain bonus, UAH | AB10: Profit after bonus, UAH | AC10: Margin check | AD10: Shelf price incl. VAT, UAH | AE10: Partner price incl. VAT, UAH | AF10: Chain bonus, UAH | AG10: Profit after bonus, UAH | AH10: Margin check | AI10: Shelf price incl. VAT, UAH | AL10: Self-Cost source, EUR/pack (before uplift)
A11: 1 | B11: SIAS — pack ramen | C11: Gouda Cheese 123 g | D11: 123 | E11: =AL11*(1+'Price 120 UAH - 33 pallets'!$G$14) -> 1.1453975 | F11: =IF(AND(ISNUMBER(E11),ISNUMBER($D$8)),E11*$D$3,NA()) -> 58.644354 | G11: =F11/$D$8 -> 115.8407 | H11: =G11*$D$4 -> 40.544245 | I11: =G11-F11-H11 -> 16.652101 | J11: =I11/G11 -> 0.14375 | K11: =G11*$D$6 -> 162.17698 | L11: =F11/(1-$D$4) -> 90.222084 | M11: =L11*$D$6 -> 126.31092 | N11: =G11-F11 -> 57.196346 | O11: =N11-H11 -> 16.652101 | P11: =$F11/(1-$D$4-$P$9) -> 167.5553 | Q11: =P11*$D$4 -> 58.644354 | R11: =P11-$F11-Q11 -> 50.26659 | S11: =R11/P11 -> 0.3 | T11: =P11*$D$6 -> 234.57742 | U11: =$F11/(1-$D$4-$U$9) -> 146.61089 | V11: =U11*$D$4 -> 51.31381 | W11: =U11-$F11-V11 -> 36.652722 | X11: =W11/U11 -> 0.25 | Y11: =U11*$D$6 -> 205.25524 | Z11: =$F11/(1-$D$4-$Z$9) -> 130.32079 | AA11: =Z11*$D$4 -> 45.612276 | AB11: =Z11-$F11-AA11 -> 26.064158 | AC11: =AB11/Z11 -> 0.2 | AD11: =Z11*$D$6 -> 182.4491 | AE11: =$F11/(1-$D$4-$AE$9) -> 117.28871 | AF11: =AE11*$D$4 -> 41.051048 | AG11: =AE11-$F11-AF11 -> 17.593306 | AH11: =AG11/AE11 -> 0.15 | AI11: =AE11*$D$6 -> 164.20419 | AL11: 1.0181312
A12: 2 | B12: SIAS — pack ramen | C12: Carbonara Spicy 131 g | D12: 131 | E12: =AL12*(1+'Price 120 UAH - 33 pallets'!$G$14) -> 1.1453975 | F12: =IF(AND(ISNUMBER(E12),ISNUMBER($D$8)),E12*$D$3,NA()) -> 58.644354 | G12: =F12/$D$8 -> 115.8407 | H12: =G12*$D$4 -> 40.544245 | I12: =G12-F12-H12 -> 16.652101 | J12: =I12/G12 -> 0.14375 | K12: =G12*$D$6 -> 162.17698 | L12: =F12/(1-$D$4) -> 90.222084 | M12: =L12*$D$6 -> 126.31092 | N12: =G12-F12 -> 57.196346 | O12: =N12-H12 -> 16.652101 | P12: =$F12/(1-$D$4-$P$9) -> 167.5553 | Q12: =P12*$D$4 -> 58.644354 | R12: =P12-$F12-Q12 -> 50.26659 | S12: =R12/P12 -> 0.3 | T12: =P12*$D$6 -> 234.57742 | U12: =$F12/(1-$D$4-$U$9) -> 146.61089 | V12: =U12*$D$4 -> 51.31381 | W12: =U12-$F12-V12 -> 36.652722 | X12: =W12/U12 -> 0.25 | Y12: =U12*$D$6 -> 205.25524 | Z12: =$F12/(1-$D$4-$Z$9) -> 130.32079 | AA12: =Z12*$D$4 -> 45.612276 | AB12: =Z12-$F12-AA12 -> 26.064158 | AC12: =AB12/Z12 -> 0.2 | AD12: =Z12*$D$6 -> 182.4491 | AE12: =$F12/(1-$D$4-$AE$9) -> 117.28871 | AF12: =AE12*$D$4 -> 41.051048 | AG12: =AE12-$F12-AF12 -> 17.593306 | AH12: =AG12/AE12 -> 0.15 | AI12: =AE12*$D$6 -> 164.20419 | AL12: 1.0181312
A13: 3 | B13: SIAS — pack ramen | C13: Vegetable Flavor 113 g | D13: 113 | E13: =AL13*(1+'Price 120 UAH - 33 pallets'!$G$14) -> 0.99267788 | F13: =IF(AND(ISNUMBER(E13),ISNUMBER($D$8)),E13*$D$3,NA()) -> 50.825107 | G13: =F13/$D$8 -> 100.39527 | H13: =G13*$D$4 -> 35.138346 | I13: =G13-F13-H13 -> 14.431821 | J13: =I13/G13 -> 0.14375 | K13: =G13*$D$6 -> 140.55338 | L13: =F13/(1-$D$4) -> 78.192473 | M13: =L13*$D$6 -> 109.46946 | N13: =G13-F13 -> 49.570166 | O13: =N13-H13 -> 14.431821 | P13: =$F13/(1-$D$4-$P$9) -> 145.21459 | Q13: =P13*$D$4 -> 50.825107 | R13: =P13-$F13-Q13 -> 43.564378 | S13: =R13/P13 -> 0.3 | T13: =P13*$D$6 -> 203.30043 | U13: =$F13/(1-$D$4-$U$9) -> 127.06277 | V13: =U13*$D$4 -> 44.471969 | W13: =U13-$F13-V13 -> 31.765692 | X13: =W13/U13 -> 0.25 | Y13: =U13*$D$6 -> 177.88788 | Z13: =$F13/(1-$D$4-$Z$9) -> 112.94468 | AA13: =Z13*$D$4 -> 39.530639 | AB13: =Z13-$F13-AA13 -> 22.588937 | AC13: =AB13/Z13 -> 0.2 | AD13: =Z13*$D$6 -> 158.12256 | AE13: =$F13/(1-$D$4-$AE$9) -> 101.65021 | AF13: =AE13*$D$4 -> 35.577575 | AG13: =AE13-$F13-AF13 -> 15.247532 | AH13: =AG13/AE13 -> 0.15 | AI13: =AE13*$D$6 -> 142.3103 | AL13: 0.88238033
A14: 4 | B14: SIAS — pack ramen | C14: Spicy Flavor 112.5 g | D14: 112.5 | E14: =AL14*(1+'Price 120 UAH - 33 pallets'!$G$14) -> 0.99267788 | F14: =IF(AND(ISNUMBER(E14),ISNUMBER($D$8)),E14*$D$3,NA()) -> 50.825107 | G14: =F14/$D$8 -> 100.39527 | H14: =G14*$D$4 -> 35.138346 | I14: =G14-F14-H14 -> 14.431821 | J14: =I14/G14 -> 0.14375 | K14: =G14*$D$6 -> 140.55338 | L14: =F14/(1-$D$4) -> 78.192473 | M14: =L14*$D$6 -> 109.46946 | N14: =G14-F14 -> 49.570166 | O14: =N14-H14 -> 14.431821 | P14: =$F14/(1-$D$4-$P$9) -> 145.21459 | Q14: =P14*$D$4 -> 50.825107 | R14: =P14-$F14-Q14 -> 43.564378 | S14: =R14/P14 -> 0.3 | T14: =P14*$D$6 -> 203.30043 | U14: =$F14/(1-$D$4-$U$9) -> 127.06277 | V14: =U14*$D$4 -> 44.471969 | W14: =U14-$F14-V14 -> 31.765692 | X14: =W14/U14 -> 0.25 | Y14: =U14*$D$6 -> 177.88788 | Z14: =$F14/(1-$D$4-$Z$9) -> 112.94468 | AA14: =Z14*$D$4 -> 39.530639 | AB14: =Z14-$F14-AA14 -> 22.588937 | AC14: =AB14/Z14 -> 0.2 | AD14: =Z14*$D$6 -> 158.12256 | AE14: =$F14/(1-$D$4-$AE$9) -> 101.65021 | AF14: =AE14*$D$4 -> 35.577575 | AG14: =AE14-$F14-AF14 -> 15.247532 | AH14: =AG14/AE14 -> 0.15 | AI14: =AE14*$D$6 -> 142.3103 | AL14: 0.88238033
A15: 5 | B15: SIAS — pack ramen | C15: Beef Flavor 113 g | D15: 113 | E15: =AL15*(1+'Price 120 UAH - 33 pallets'!$G$14) -> 0.99267788 | F15: =IF(AND(ISNUMBER(E15),ISNUMBER($D$8)),E15*$D$3,NA()) -> 50.825107 | G15: =F15/$D$8 -> 100.39527 | H15: =G15*$D$4 -> 35.138346 | I15: =G15-F15-H15 -> 14.431821 | J15: =I15/G15 -> 0.14375 | K15: =G15*$D$6 -> 140.55338 | L15: =F15/(1-$D$4) -> 78.192473 | M15: =L15*$D$6 -> 109.46946 | N15: =G15-F15 -> 49.570166 | O15: =N15-H15 -> 14.431821 | P15: =$F15/(1-$D$4-$P$9) -> 145.21459 | Q15: =P15*$D$4 -> 50.825107 | R15: =P15-$F15-Q15 -> 43.564378 | S15: =R15/P15 -> 0.3 | T15: =P15*$D$6 -> 203.30043 | U15: =$F15/(1-$D$4-$U$9) -> 127.06277 | V15: =U15*$D$4 -> 44.471969 | W15: =U15-$F15-V15 -> 31.765692 | X15: =W15/U15 -> 0.25 | Y15: =U15*$D$6 -> 177.88788 | Z15: =$F15/(1-$D$4-$Z$9) -> 112.94468 | AA15: =Z15*$D$4 -> 39.530639 | AB15: =Z15-$F15-AA15 -> 22.588937 | AC15: =AB15/Z15 -> 0.2 | AD15: =Z15*$D$6 -> 158.12256 | AE15: =$F15/(1-$D$4-$AE$9) -> 101.65021 | AF15: =AE15*$D$4 -> 35.577575 | AG15: =AE15-$F15-AF15 -> 15.247532 | AH15: =AG15/AE15 -> 0.15 | AI15: =AE15*$D$6 -> 142.3103 | AL15: 0.88238033
A16: 6 | B16: SIAS — pack ramen | C16: Chicken Flavor 113 g | D16: 113 | E16: =AL16*(1+'Price 120 UAH - 33 pallets'!$G$14) -> 0.99267788 | F16: =IF(AND(ISNUMBER(E16),ISNUMBER($D$8)),E16*$D$3,NA()) -> 50.825107 | G16: =F16/$D$8 -> 100.39527 | H16: =G16*$D$4 -> 35.138346 | I16: =G16-F16-H16 -> 14.431821 | J16: =I16/G16 -> 0.14375 | K16: =G16*$D$6 -> 140.55338 | L16: =F16/(1-$D$4) -> 78.192473 | M16: =L16*$D$6 -> 109.46946 | N16: =G16-F16 -> 49.570166 | O16: =N16-H16 -> 14.431821 | P16: =$F16/(1-$D$4-$P$9) -> 145.21459 | Q16: =P16*$D$4 -> 50.825107 | R16: =P16-$F16-Q16 -> 43.564378 | S16: =R16/P16 -> 0.3 | T16: =P16*$D$6 -> 203.30043 | U16: =$F16/(1-$D$4-$U$9) -> 127.06277 | V16: =U16*$D$4 -> 44.471969 | W16: =U16-$F16-V16 -> 31.765692 | X16: =W16/U16 -> 0.25 | Y16: =U16*$D$6 -> 177.88788 | Z16: =$F16/(1-$D$4-$Z$9) -> 112.94468 | AA16: =Z16*$D$4 -> 39.530639 | AB16: =Z16-$F16-AA16 -> 22.588937 | AC16: =AB16/Z16 -> 0.2 | AD16: =Z16*$D$6 -> 158.12256 | AE16: =$F16/(1-$D$4-$AE$9) -> 101.65021 | AF16: =AE16*$D$4 -> 35.577575 | AG16: =AE16-$F16-AF16 -> 15.247532 | AH16: =AG16/AE16 -> 0.15 | AI16: =AE16*$D$6 -> 142.3103 | AL16: 0.88238033
B19: Each step of price formation — per your example
A21: № | B21: What we calculate | D21: Action | F21: =C11 -> Gouda Cheese 123 g | G21: =C12 -> Carbonara Spicy 131 g | H21: =C13 -> Vegetable Flavor 113 g | I21: =C14 -> Spicy Flavor 112.5 g | J21: =C15 -> Beef Flavor 113 g | K21: =C16 -> Chicken Flavor 113 g
A22: 1 | B22: Landed cost in Ukraine, EUR/pack | D22: From Self-Cost | F22: =E11 -> 1.1453975 | G22: =E12 -> 1.1453975 | H22: =E13 -> 0.99267788 | I22: =E14 -> 0.99267788 | J22: =E15 -> 0.99267788 | K22: =E16 -> 0.99267788
A23: 2 | B23: Rate, UAH/EUR | D23: Input in D3 | F23: =$D$3 -> 51.2 | G23: =$D$3 -> 51.2 | H23: =$D$3 -> 51.2 | I23: =$D$3 -> 51.2 | J23: =$D$3 -> 51.2 | K23: =$D$3 -> 51.2
A24: 3 | B24: Landed cost in Ukraine, UAH/pack | D24: Step 1 × step 2 | F24: =F11 -> 58.644354 | G24: =F12 -> 58.644354 | H24: =F13 -> 50.825107 | I24: =F14 -> 50.825107 | J24: =F15 -> 50.825107 | K24: =F16 -> 50.825107
A25: 4 | B25: Full partner price, % | D25: Base for all percentages | F25: 1 | G25: 1 | H25: 1 | I25: 1 | J25: 1 | K25: 1
A26: 5 | B26: Chain bonus, % | D26: Input in D4 | F26: =$D$4 -> 0.35 | G26: =$D$4 -> 0.35 | H26: =$D$4 -> 0.35 | I26: =$D$4 -> 0.35 | J26: =$D$4 -> 0.35 | K26: =$D$4 -> 0.35
A27: 6 | B27: Share of price after bonus, % | D27: Step 4 − step 5 | F27: =1-$D$4 -> 0.65 | G27: =1-$D$4 -> 0.65 | H27: =1-$D$4 -> 0.65 | I27: =1-$D$4 -> 0.65 | J27: =1-$D$4 -> 0.65 | K27: =1-$D$4 -> 0.65
A28: 7 | B28: Our target margin, % | D28: Input in D5 | F28: =$D$5 -> 0.14375 | G28: =$D$5 -> 0.14375 | H28: =$D$5 -> 0.14375 | I28: =$D$5 -> 0.14375 | J28: =$D$5 -> 0.14375 | K28: =$D$5 -> 0.14375
A29: 8 | B29: Share of price for landed cost, % | D29: Step 6 − step 7 | F29: =$D$8 -> 0.50625 | G29: =$D$8 -> 0.50625 | H29: =$D$8 -> 0.50625 | I29: =$D$8 -> 0.50625 | J29: =$D$8 -> 0.50625 | K29: =$D$8 -> 0.50625
A30: 9 | B30: Partner price incl. VAT, UAH/pack | D30: Step 3 ÷ step 8 | F30: =G11 -> 115.8407 | G30: =G12 -> 115.8407 | H30: =G13 -> 100.39527 | I30: =G14 -> 100.39527 | J30: =G15 -> 100.39527 | K30: =G16 -> 100.39527
A31: 10 | B31: Gross profit before bonus, UAH/pack | D31: Step 9 − step 3 | F31: =N11 -> 57.196346 | G31: =N12 -> 57.196346 | H31: =N13 -> 49.570166 | I31: =N14 -> 49.570166 | J31: =N15 -> 49.570166 | K31: =N16 -> 49.570166
A32: 11 | B32: Chain bonus, UAH/pack | D32: Step 9 × step 5 | F32: =H11 -> 40.544245 | G32: =H12 -> 40.544245 | H32: =H13 -> 35.138346 | I32: =H14 -> 35.138346 | J32: =H15 -> 35.138346 | K32: =H16 -> 35.138346
A33: 12 | B33: Left for us after landed cost and bonus, UAH/pack | D33: Step 10 − step 11 | F33: =I11 -> 16.652101 | G33: =I12 -> 16.652101 | H33: =I13 -> 14.431821 | I33: =I14 -> 14.431821 | J33: =I15 -> 14.431821 | K33: =I16 -> 14.431821
A34: 13 | B34: Check of our margin after bonus, % | D34: Step 12 ÷ step 9 | F34: =J11 -> 0.14375 | G34: =J12 -> 0.14375 | H34: =J13 -> 0.14375 | I34: =J14 -> 0.14375 | J34: =J15 -> 0.14375 | K34: =J16 -> 0.14375
A35: 14 | B35: Retailer markup for shelf, % | D35: Multiplier D6 − 1 | F35: =$D$6-1 -> 0.4 | G35: =$D$6-1 -> 0.4 | H35: =$D$6-1 -> 0.4 | I35: =$D$6-1 -> 0.4 | J35: =$D$6-1 -> 0.4 | K35: =$D$6-1 -> 0.4
A36: 15 | B36: Retailer multiplier | D36: 1 + step 14 | F36: =$D$6 -> 1.4 | G36: =$D$6 -> 1.4 | H36: =$D$6 -> 1.4 | I36: =$D$6 -> 1.4 | J36: =$D$6 -> 1.4 | K36: =$D$6 -> 1.4
A37: 16 | B37: Shelf price incl. VAT, UAH/pack | D37: Step 9 × step 15 | F37: =K11 -> 162.17698 | G37: =K12 -> 162.17698 | H37: =K13 -> 140.55338 | I37: =K14 -> 140.55338 | J37: =K15 -> 140.55338 | K37: =K16 -> 140.55338
A38: 17 | B38: Partner price at zero profit for us, UAH/pack | D38: Step 3 ÷ step 6 | F38: =L11 -> 90.222084 | G38: =L12 -> 90.222084 | H38: =L13 -> 78.192473 | I38: =L14 -> 78.192473 | J38: =L15 -> 78.192473 | K38: =L16 -> 78.192473
A39: 18 | B39: Shelf price at zero profit for us, UAH/pack | D39: Step 17 × step 15 | F39: =M11 -> 126.31092 | G39: =M12 -> 126.31092 | H39: =M13 -> 109.46946 | I39: =M14 -> 109.46946 | J39: =M15 -> 109.46946 | K39: =M16 -> 109.46946

Sheet Price 120 UAH - 6 pallets
A1: INTERNAL — not for SIAS · real bonus 35 %, proportional cost uplift (G14) · 6 pallets
A2: REQUEST TO SIAS, €/pack | B2: =B20 -> 0.32 | D2: ="now €"&B5&" (4 SKUs) / €"&B7&" (2 SKUs)" -> now €0.65 (4 SKUs) / €0.75 (2 SKUs) | F2: ="reduction −"&ROUND((1-B20/B5)*100,0)&" % / −"&ROUND((1-B20/B7)*100,0)&" %" -> reduction −51 % / −57 % | H2: one price for all 6 SKUs
A3: Scenario | B3: SIAS purchase per pack | C3: ="Landed cost in Ukraine"&CHAR(10)&"product + costs in Ukraine"&IF(G14>0," + "&ROUND(G14*100,1)&" % uplift","") -> Landed cost in Ukraine product + costs in Ukraine + 12.5 % uplift | D3: Partner price cost ÷ (1 − bonus − margin) | E3: ="Chain bonus (shown)"&CHAR(10)&ROUND(D14*100,0)&" % of partner price" -> Chain bonus (shown) 35 % of partner price | F3: ="Our profit"&CHAR(10)&ROUND(C14*100,0)&" % of partner price" -> Our profit 14 % of partner price | G3: Store markup +40 % on partner price | H3: SHELF PRICE incl. VAT partner price × 1.40
A4: BEFORE · Vegetable, Spicy, Beef, Chicken (4 SKUs) | B4: =B5*F14 -> 33.28 | C4: =$B$24*F14*(1+$G$14) -> 65.3211 | D4: =C4/(1-D14-C14) -> 129.02933 | E4: =D4*D14 -> 45.160267 | F4: =D4-C4-E4 -> 18.547967 | G4: =D4*(E14-1) -> 51.611733 | H4: =D4*E14 -> 180.64107
B5: 0.65 | C5: =C4/F14 -> 1.2758027 | D5: =D4/F14 -> 2.5201042 | E5: =E4/F14 -> 0.88203646 | F5: =F4/F14 -> 0.36226497 | G5: =G4/F14 -> 1.0080417 | H5: =H4/F14 -> 3.5281458
A6: BEFORE · Gouda Cheese, Carbonara Spicy (2 SKUs) | B6: =B7*F14 -> 38.4 | C6: =$B$25*F14*(1+$G$14) -> 75.3705 | D6: =C6/(1-D14-C14) -> 148.88 | E6: =D6*D14 -> 52.108 | F6: =D6-C6-E6 -> 21.4015 | G6: =D6*(E14-1) -> 59.552 | H6: =D6*E14 -> 208.432
B7: 0.75 | C7: =C6/F14 -> 1.4720801 | D7: =D6/F14 -> 2.9078125 | E7: =E6/F14 -> 1.0177344 | F7: =F6/F14 -> 0.41799805 | G7: =G6/F14 -> 1.163125 | H7: =H6/F14 -> 4.0709375
A8: AFTER · SIAS request (all 6 SKUs) | B8: =B9*F14 -> 16.384 | C8: =B22 -> 42.92946 | D8: =C8/(1-D14-C14) -> 84.798933 | E8: =D8*D14 -> 29.679627 | F8: =D8-C8-E8 -> 12.189847 | G8: =D8*(E14-1) -> 33.919573 | H8: =D8*E14 -> 118.71851
B9: =B20 -> 0.32 | C9: =C8/F14 -> 0.83846602 | D9: =D8/F14 -> 1.6562292 | E9: =E8/F14 -> 0.57968021 | F9: =F8/F14 -> 0.23808294 | G9: =G8/F14 -> 0.66249167 | H9: =H8/F14 -> 2.3187208
A10: CHANGE: AFTER − BEFORE (4 SKUs) | B10: =B8-B4 -> -16.896 | C10: =C8-C4 -> -22.39164 | D10: =D8-D4 -> -44.2304 | E10: =E8-E4 -> -15.48064 | F10: =F8-F4 -> -6.35812 | G10: =G8-G4 -> -17.69216 | H10: =H8-H4 -> -61.92256
B11: =B9-B5 -> -0.33 | C11: =C9-C5 -> -0.43733672 | D11: =D9-D5 -> -0.863875 | E11: =E9-E5 -> -0.30235625 | F11: =F9-F5 -> -0.12418203 | G11: =G9-G5 -> -0.34555 | H11: =H9-H5 -> -1.209425
A12: INPUTS — yellow cells can be changed, green ones are linked from the sheet "Model 6 pallets"
B13: Shelf price, ₴ | C13: Margin shown (auto: offsets the cost uplift) | D13: Chain bonus (shown) | E13: Shelf multiplier | F13: Rate ₴/€ | G13: Cost uplift, % of landed cost (assumption) | H13: Base share of price for cost (real model: 1 − 25 % − 30 %)
A14: Target and model terms | B14: 120 | C14: =1-D14-H14*(1+G14) -> 0.14375 | D14: ='Model 6 pallets'!D4 -> 0.35 | E14: ='Model 6 pallets'!D6 -> 1.4 | F14: ='Model 6 pallets'!D3 -> 51.2 | G14: 0.125 | H14: 0.45
B15: Import VAT | C15: Financing | D15: Customs duty | E15: Batch freight, € | F15: Broker, € | G15: Other, €
B16: 0.2 | C16: 0.025 | D16: 0 | E16: 2600 | F16: 288 | G16: 42
B17: Freight share in customs value | C17: Pallets in batch | D17: Packs per pallet
B18: 0.7 | C18: 6 | D18: 1600
A20: Request to SIAS, €/pack (rounded down to the euro cent) | B20: =ROUNDDOWN(((B14/E14*(1-D14-C14)/(1+G14))/F14/(1+C16)-(E16+F16+G16+E16*B18*(D16+B16*(1+D16)))/(C18*D18))/((1+D16)*(1+B16)),2) -> 0.32
A21: Maximum purchase price before rounding, €/pack | B21: =((B14/E14*(1-D14-C14)/(1+G14))/F14/(1+C16)-(E16+F16+G16+E16*B18*(D16+B16*(1+D16)))/(C18*D18))/((1+D16)*(1+B16)) -> 0.32654072
A22: Landed cost in Ukraine at the request (incl. uplift), ₴/pack | B22: =(B20*F14+(E16+F16+G16)/(C18*D18)*F14+(B20+E16*B18/(C18*D18))*D16*F14+(B20+E16*B18/(C18*D18))*(1+D16)*B16*F14)*(1+C16)*(1+G14) -> 42.92946
A24: Landed cost, 4 SKUs (Vegetable…), €/pack — Self-Cost (col. B) → after uplift (col. C) | B24: ='Model 6 pallets'!AL13 -> 1.1340469 | C24: =B24*(1+$G$14) -> 1.2758027
A25: Landed cost, 2 SKUs (Gouda, Carbonara), €/pack — Self-Cost (col. B) → after uplift (col. C) | B25: ='Model 6 pallets'!AL11 -> 1.3085156 | C25: =B25*(1+$G$14) -> 1.4720801

Sheet Price 120 UAH - 33 pallets
A1: INTERNAL — not for SIAS · real bonus 35 %, proportional cost uplift (G14) · 33 pallets (Full Truck)
A2: REQUEST TO SIAS, €/pack | B2: =B19 -> 0.54 | D2: ="now €"&B5&" (4 SKUs) / €"&B7&" (2 SKUs)" -> now €0.65 (4 SKUs) / €0.75 (2 SKUs) | F2: ="reduction −"&ROUND((1-B19/B5)*100,0)&" % / −"&ROUND((1-B19/B7)*100,0)&" %" -> reduction −17 % / −28 % | H2: one price for all 6 SKUs
A3: Scenario | B3: SIAS purchase per pack | C3: ="Landed cost in Ukraine"&CHAR(10)&"product + costs in Ukraine"&IF(G14>0," + "&ROUND(G14*100,1)&" % uplift","") -> Landed cost in Ukraine product + costs in Ukraine + 12.5 % uplift | D3: Partner price cost ÷ (1 − bonus − margin) | E3: ="Chain bonus (shown)"&CHAR(10)&ROUND(D14*100,0)&" % of partner price" -> Chain bonus (shown) 35 % of partner price | F3: ="Our profit"&CHAR(10)&ROUND(C14*100,0)&" % of partner price" -> Our profit 14 % of partner price | G3: Store markup +40 % on partner price | H3: SHELF PRICE incl. VAT partner price × 1.40
A4: BEFORE · Vegetable, Spicy, Beef, Chicken (4 SKUs) | B4: =B5*F14 -> 33.28 | C4: =$B$23*F14*(1+$G$14) -> 50.825107 | D4: =C4/(1-D14-C14) -> 100.39527 | E4: =D4*D14 -> 35.138346 | F4: =D4-C4-E4 -> 14.431821 | G4: =D4*(E14-1) -> 40.158109 | H4: =D4*E14 -> 140.55338
B5: 0.65 | C5: =C4/F14 -> 0.99267788 | D5: =D4/F14 -> 1.9608452 | E5: =E4/F14 -> 0.68629582 | F5: =F4/F14 -> 0.2818715 | G5: =G4/F14 -> 0.78433807 | H5: =H4/F14 -> 2.7451833
A6: BEFORE · Gouda Cheese, Carbonara Spicy (2 SKUs) | B6: =B7*F14 -> 38.4 | C6: =$B$24*F14*(1+$G$14) -> 58.644354 | D6: =C6/(1-D14-C14) -> 115.8407 | E6: =D6*D14 -> 40.544245 | F6: =D6-C6-E6 -> 16.652101 | G6: =D6*(E14-1) -> 46.33628 | H6: =D6*E14 -> 162.17698
B7: 0.75 | C7: =C6/F14 -> 1.1453975 | D7: =D6/F14 -> 2.2625137 | E7: =E6/F14 -> 0.79187979 | F7: =F6/F14 -> 0.32523634 | G7: =G6/F14 -> 0.90500547 | H7: =H6/F14 -> 3.1675191
A8: AFTER · SIAS request (all 6 SKUs) | B8: =B9*F14 -> 27.648 | C8: =B21 -> 43.343411 | D8: =C8/(1-D14-C14) -> 85.616614 | E8: =D8*D14 -> 29.965815 | F8: =D8-C8-E8 -> 12.307388 | G8: =D8*(E14-1) -> 34.246646 | H8: =D8*E14 -> 119.86326
B9: =B19 -> 0.54 | C9: =C8/F14 -> 0.84655099 | D9: =D8/F14 -> 1.6721995 | E9: =E8/F14 -> 0.58526982 | F9: =F8/F14 -> 0.24037868 | G9: =G8/F14 -> 0.6688798 | H9: =H8/F14 -> 2.3410793
A10: CHANGE: AFTER − BEFORE (4 SKUs) | B10: =B8-B4 -> -5.632 | C10: =C8-C4 -> -7.4816963 | D10: =D8-D4 -> -14.778659 | E10: =E8-E4 -> -5.1725308 | F10: =F8-F4 -> -2.1244323 | G10: =G8-G4 -> -5.9114638 | H10: =H8-H4 -> -20.690123
B11: =B9-B5 -> -0.11 | C11: =C9-C5 -> -0.14612688 | D11: =D9-D5 -> -0.28864569 | E11: =E9-E5 -> -0.10102599 | F11: =F9-F5 -> -0.041492818 | G11: =G9-G5 -> -0.11545828 | H11: =H9-H5 -> -0.40410397
A12: INPUTS — yellow cells can be changed, green ones are linked from the sheet "Model 33 pallets"
B13: Shelf price, ₴ | C13: Margin shown (auto: offsets the cost uplift) | D13: Chain bonus (shown) | E13: Shelf multiplier | F13: Rate ₴/€ | G13: Cost uplift, % of landed cost (assumption) | H13: Base share of price for cost (real model: 1 − 25 % − 30 %)
A14: Target and model terms | B14: 120 | C14: =1-D14-H14*(1+G14) -> 0.14375 | D14: ='Model 33 pallets'!D4 -> 0.35 | E14: ='Model 33 pallets'!D6 -> 1.4 | F14: ='Model 33 pallets'!D3 -> 51.2 | G14: 0.125 | H14: 0.45
B15: Import VAT | C15: Financing | D15: Customs duty | E15: Batch freight, € | F15: Broker, € | G15: Other, €
B16: 0.2 | C16: 0.025 | D16: 0 | E16: 3700 | F16: 288 | G16: 42
B17: Freight share in customs value | C17: Pallets in batch | D17: Packs per pallet
B18: 0.7 | C18: 33 | D18: 1600
A19: Request to SIAS, €/pack (rounded down to the euro cent) | B19: =ROUNDDOWN(((B14/E14*(1-D14-C14)/(1+G14))/F14/(1+C16)-(E16+F16+G16+E16*B18*(D16+B16*(1+D16)))/(C18*D18))/((1+D16)*(1+B16)),2) -> 0.54
A20: Maximum purchase price before rounding, €/pack | B20: =((B14/E14*(1-D14-C14)/(1+G14))/F14/(1+C16)-(E16+F16+G16+E16*B18*(D16+B16*(1+D16)))/(C18*D18))/((1+D16)*(1+B16)) -> 0.54069792
A21: Landed cost in Ukraine at the request (incl. uplift), ₴/pack | B21: =(B19*F14+(E16+F16+G16)/(C18*D18)*F14+(B19+E16*B18/(C18*D18))*D16*F14+(B19+E16*B18/(C18*D18))*(1+D16)*B16*F14)*(1+C16)*(1+G14) -> 43.343411
A23: Landed cost, 4 SKUs (Vegetable…), €/pack — Self-Cost (col. B) → after uplift (col. C) | B23: ='Model 33 pallets'!AL13 -> 0.88238033 | C23: =B23*(1+$G$14) -> 0.99267788
A24: Landed cost, 2 SKUs (Gouda, Carbonara), €/pack — Self-Cost (col. B) → after uplift (col. C) | B24: ='Model 33 pallets'!AL11 -> 1.0181312 | C24: =B24*(1+$G$14) -> 1.1453975

Sheet Scenarios
A1: INTERNAL FILE — for us only · Price-structure scenarios with a proportional cost uplift
A2: ="Allowed (shown) landed cost = partner price × (1 − bonus − margin); product landed cost = that budget ÷ (1 + uplift). 1 p.p. of margin or bonus = "&ROUND(E5/100,2)&" ₴ per pack = €"&ROUND(E5/100/D5/(1+C5)/((1+G5)*(1+F5)),4)&" on the request." -> Allowed (shown) landed cost = partner price × (1 − bonus − margin); product landed cost = that budget ÷ (1 + uplift). 1 p.p. of margin or bonus = 0.86 ₴ per pack = €0.0136 on the request.
A4: Shelf price, ₴ | B4: Shelf multiplier | C4: Financing | D4: Rate ₴/€ | E4: Partner price at shelf price, ₴ | F4: Import VAT | G4: Customs duty
A5: ='Price 120 UAH - 33 pallets'!B14 -> 120 | B5: ='Price 120 UAH - 33 pallets'!E14 -> 1.4 | C5: ='Price 120 UAH - 33 pallets'!C16 -> 0.025 | D5: ='Price 120 UAH - 33 pallets'!F14 -> 51.2 | E5: =A5/B5 -> 85.714286 | F5: ='Price 120 UAH - 33 pallets'!B16 -> 0.2 | G5: ='Price 120 UAH - 33 pallets'!D16 -> 0
A7: Scenario | B7: Chain bonus | C7: Margin shown | D7: Cost uplift, % of landed cost | E7: Chain bonus, ₴ | F7: Our profit, ₴ | G7: Landed-cost budget (shown cost), ₴ | H7: Product landed cost allowed (budget ÷ (1 + uplift)), ₴ | I7: 33 pallets: max purchase, € | J7: 33 pallets: REQUEST TO SIAS, € | K7: vs current €0.65, % | L7: 6 pallets: max purchase, € | M7: 6 pallets: REQUEST TO SIAS, € | N7: vs current €0.65, %
A8: BASE · previous version of the model
A9: Previous: bonus 25 % + margin 30 % | B9: 0.25 | C9: 0.3 | D9: 0 | E9: =$E$5*B9 -> 21.428571 | F9: =$E$5*C9 -> 25.714286 | G9: =$E$5-E9-F9 -> 38.571429 | H9: =G9/(1+D9) -> 38.571429 | I9: =(($H9/$D$5/(1+$C$5)-('Price 120 UAH - 33 pallets'!E16+'Price 120 UAH - 33 pallets'!F16+'Price 120 UAH - 33 pallets'!G16+'Price 120 UAH - 33 pallets'!E16*'Price 120 UAH - 33 pallets'!B18*($G$5+$F$5*(1+$G$5)))/('Price 120 UAH - 33 pallets'!C18*'Price 120 UAH - 33 pallets'!D18))/((1+$G$5)*(1+$F$5))) -> 0.54069792 | J9: =ROUNDDOWN((($H9/$D$5/(1+$C$5)-('Price 120 UAH - 33 pallets'!E16+'Price 120 UAH - 33 pallets'!F16+'Price 120 UAH - 33 pallets'!G16+'Price 120 UAH - 33 pallets'!E16*'Price 120 UAH - 33 pallets'!B18*($G$5+$F$5*(1+$G$5)))/('Price 120 UAH - 33 pallets'!C18*'Price 120 UAH - 33 pallets'!D18))/((1+$G$5)*(1+$F$5))),2) -> 0.54 | K9: =J9/0.65-1 -> -0.16923077 | L9: =(($H9/$D$5/(1+$C$5)-('Price 120 UAH - 6 pallets'!E16+'Price 120 UAH - 6 pallets'!F16+'Price 120 UAH - 6 pallets'!G16+'Price 120 UAH - 6 pallets'!E16*'Price 120 UAH - 6 pallets'!B18*($G$5+$F$5*(1+$G$5)))/('Price 120 UAH - 6 pallets'!C18*'Price 120 UAH - 6 pallets'!D18))/((1+$G$5)*(1+$F$5))) -> 0.32654072 | M9: =ROUNDDOWN((($H9/$D$5/(1+$C$5)-('Price 120 UAH - 6 pallets'!E16+'Price 120 UAH - 6 pallets'!F16+'Price 120 UAH - 6 pallets'!G16+'Price 120 UAH - 6 pallets'!E16*'Price 120 UAH - 6 pallets'!B18*($G$5+$F$5*(1+$G$5)))/('Price 120 UAH - 6 pallets'!C18*'Price 120 UAH - 6 pallets'!D18))/((1+$G$5)*(1+$F$5))),2) -> 0.32 | N9: =M9/0.65-1 -> -0.50769231
A10: SAME REQUEST PRICE, different structure (uplift matched to the sum of bonus + margin)
A11: ★ Chain bonus 35 % + margin 20 % (no uplift) | B11: 0.35 | C11: 0.2 | D11: 0 | E11: =$E$5*B11 -> 30 | F11: =$E$5*C11 -> 17.142857 | G11: =$E$5-E11-F11 -> 38.571429 | H11: =G11/(1+D11) -> 38.571429 | I11: =(($H11/$D$5/(1+$C$5)-('Price 120 UAH - 33 pallets'!E16+'Price 120 UAH - 33 pallets'!F16+'Price 120 UAH - 33 pallets'!G16+'Price 120 UAH - 33 pallets'!E16*'Price 120 UAH - 33 pallets'!B18*($G$5+$F$5*(1+$G$5)))/('Price 120 UAH - 33 pallets'!C18*'Price 120 UAH - 33 pallets'!D18))/((1+$G$5)*(1+$F$5))) -> 0.54069792 | J11: =ROUNDDOWN((($H11/$D$5/(1+$C$5)-('Price 120 UAH - 33 pallets'!E16+'Price 120 UAH - 33 pallets'!F16+'Price 120 UAH - 33 pallets'!G16+'Price 120 UAH - 33 pallets'!E16*'Price 120 UAH - 33 pallets'!B18*($G$5+$F$5*(1+$G$5)))/('Price 120 UAH - 33 pallets'!C18*'Price 120 UAH - 33 pallets'!D18))/((1+$G$5)*(1+$F$5))),2) -> 0.54 | K11: =J11/0.65-1 -> -0.16923077 | L11: =(($H11/$D$5/(1+$C$5)-('Price 120 UAH - 6 pallets'!E16+'Price 120 UAH - 6 pallets'!F16+'Price 120 UAH - 6 pallets'!G16+'Price 120 UAH - 6 pallets'!E16*'Price 120 UAH - 6 pallets'!B18*($G$5+$F$5*(1+$G$5)))/('Price 120 UAH - 6 pallets'!C18*'Price 120 UAH - 6 pallets'!D18))/((1+$G$5)*(1+$F$5))) -> 0.32654072 | M11: =ROUNDDOWN((($H11/$D$5/(1+$C$5)-('Price 120 UAH - 6 pallets'!E16+'Price 120 UAH - 6 pallets'!F16+'Price 120 UAH - 6 pallets'!G16+'Price 120 UAH - 6 pallets'!E16*'Price 120 UAH - 6 pallets'!B18*($G$5+$F$5*(1+$G$5)))/('Price 120 UAH - 6 pallets'!C18*'Price 120 UAH - 6 pallets'!D18))/((1+$G$5)*(1+$F$5))),2) -> 0.32 | N11: =M11/0.65-1 -> -0.50769231
A12: Bonus 30 % + margin 25 % (no uplift) | B12: 0.3 | C12: 0.25 | D12: 0 | E12: =$E$5*B12 -> 25.714286 | F12: =$E$5*C12 -> 21.428571 | G12: =$E$5-E12-F12 -> 38.571429 | H12: =G12/(1+D12) -> 38.571429 | I12: =(($H12/$D$5/(1+$C$5)-('Price 120 UAH - 33 pallets'!E16+'Price 120 UAH - 33 pallets'!F16+'Price 120 UAH - 33 pallets'!G16+'Price 120 UAH - 33 pallets'!E16*'Price 120 UAH - 33 pallets'!B18*($G$5+$F$5*(1+$G$5)))/('Price 120 UAH - 33 pallets'!C18*'Price 120 UAH - 33 pallets'!D18))/((1+$G$5)*(1+$F$5))) -> 0.54069792 | J12: =ROUNDDOWN((($H12/$D$5/(1+$C$5)-('Price 120 UAH - 33 pallets'!E16+'Price 120 UAH - 33 pallets'!F16+'Price 120 UAH - 33 pallets'!G16+'Price 120 UAH - 33 pallets'!E16*'Price 120 UAH - 33 pallets'!B18*($G$5+$F$5*(1+$G$5)))/('Price 120 UAH - 33 pallets'!C18*'Price 120 UAH - 33 pallets'!D18))/((1+$G$5)*(1+$F$5))),2) -> 0.54 | K12: =J12/0.65-1 -> -0.16923077 | L12: =(($H12/$D$5/(1+$C$5)-('Price 120 UAH - 6 pallets'!E16+'Price 120 UAH - 6 pallets'!F16+'Price 120 UAH - 6 pallets'!G16+'Price 120 UAH - 6 pallets'!E16*'Price 120 UAH - 6 pallets'!B18*($G$5+$F$5*(1+$G$5)))/('Price 120 UAH - 6 pallets'!C18*'Price 120 UAH - 6 pallets'!D18))/((1+$G$5)*(1+$F$5))) -> 0.32654072 | M12: =ROUNDDOWN((($H12/$D$5/(1+$C$5)-('Price 120 UAH - 6 pallets'!E16+'Price 120 UAH - 6 pallets'!F16+'Price 120 UAH - 6 pallets'!G16+'Price 120 UAH - 6 pallets'!E16*'Price 120 UAH - 6 pallets'!B18*($G$5+$F$5*(1+$G$5)))/('Price 120 UAH - 6 pallets'!C18*'Price 120 UAH - 6 pallets'!D18))/((1+$G$5)*(1+$F$5))),2) -> 0.32 | N12: =M12/0.65-1 -> -0.50769231
A13: Bonus 25 % + margin 20 % + uplift matched to the same request | B13: 0.25 | C13: 0.2 | D13: =(1-B13-C13)/(1-$B$9-$C$9)-1 -> 0.22222222 | E13: =$E$5*B13 -> 21.428571 | F13: =$E$5*C13 -> 17.142857 | G13: =$E$5-E13-F13 -> 47.142857 | H13: =G13/(1+D13) -> 38.571429 | I13: =(($H13/$D$5/(1+$C$5)-('Price 120 UAH - 33 pallets'!E16+'Price 120 UAH - 33 pallets'!F16+'Price 120 UAH - 33 pallets'!G16+'Price 120 UAH - 33 pallets'!E16*'Price 120 UAH - 33 pallets'!B18*($G$5+$F$5*(1+$G$5)))/('Price 120 UAH - 33 pallets'!C18*'Price 120 UAH - 33 pallets'!D18))/((1+$G$5)*(1+$F$5))) -> 0.54069792 | J13: =ROUNDDOWN((($H13/$D$5/(1+$C$5)-('Price 120 UAH - 33 pallets'!E16+'Price 120 UAH - 33 pallets'!F16+'Price 120 UAH - 33 pallets'!G16+'Price 120 UAH - 33 pallets'!E16*'Price 120 UAH - 33 pallets'!B18*($G$5+$F$5*(1+$G$5)))/('Price 120 UAH - 33 pallets'!C18*'Price 120 UAH - 33 pallets'!D18))/((1+$G$5)*(1+$F$5))),2) -> 0.54 | K13: =J13/0.65-1 -> -0.16923077 | L13: =(($H13/$D$5/(1+$C$5)-('Price 120 UAH - 6 pallets'!E16+'Price 120 UAH - 6 pallets'!F16+'Price 120 UAH - 6 pallets'!G16+'Price 120 UAH - 6 pallets'!E16*'Price 120 UAH - 6 pallets'!B18*($G$5+$F$5*(1+$G$5)))/('Price 120 UAH - 6 pallets'!C18*'Price 120 UAH - 6 pallets'!D18))/((1+$G$5)*(1+$F$5))) -> 0.32654072 | M13: =ROUNDDOWN((($H13/$D$5/(1+$C$5)-('Price 120 UAH - 6 pallets'!E16+'Price 120 UAH - 6 pallets'!F16+'Price 120 UAH - 6 pallets'!G16+'Price 120 UAH - 6 pallets'!E16*'Price 120 UAH - 6 pallets'!B18*($G$5+$F$5*(1+$G$5)))/('Price 120 UAH - 6 pallets'!C18*'Price 120 UAH - 6 pallets'!D18))/((1+$G$5)*(1+$F$5))),2) -> 0.32 | N13: =M13/0.65-1 -> -0.50769231
A14: Bonus 25 % + margin 25 % + uplift matched to the same request | B14: 0.25 | C14: 0.25 | D14: =(1-B14-C14)/(1-$B$9-$C$9)-1 -> 0.11111111 | E14: =$E$5*B14 -> 21.428571 | F14: =$E$5*C14 -> 21.428571 | G14: =$E$5-E14-F14 -> 42.857143 | H14: =G14/(1+D14) -> 38.571429 | I14: =(($H14/$D$5/(1+$C$5)-('Price 120 UAH - 33 pallets'!E16+'Price 120 UAH - 33 pallets'!F16+'Price 120 UAH - 33 pallets'!G16+'Price 120 UAH - 33 pallets'!E16*'Price 120 UAH - 33 pallets'!B18*($G$5+$F$5*(1+$G$5)))/('Price 120 UAH - 33 pallets'!C18*'Price 120 UAH - 33 pallets'!D18))/((1+$G$5)*(1+$F$5))) -> 0.54069792 | J14: =ROUNDDOWN((($H14/$D$5/(1+$C$5)-('Price 120 UAH - 33 pallets'!E16+'Price 120 UAH - 33 pallets'!F16+'Price 120 UAH - 33 pallets'!G16+'Price 120 UAH - 33 pallets'!E16*'Price 120 UAH - 33 pallets'!B18*($G$5+$F$5*(1+$G$5)))/('Price 120 UAH - 33 pallets'!C18*'Price 120 UAH - 33 pallets'!D18))/((1+$G$5)*(1+$F$5))),2) -> 0.54 | K14: =J14/0.65-1 -> -0.16923077 | L14: =(($H14/$D$5/(1+$C$5)-('Price 120 UAH - 6 pallets'!E16+'Price 120 UAH - 6 pallets'!F16+'Price 120 UAH - 6 pallets'!G16+'Price 120 UAH - 6 pallets'!E16*'Price 120 UAH - 6 pallets'!B18*($G$5+$F$5*(1+$G$5)))/('Price 120 UAH - 6 pallets'!C18*'Price 120 UAH - 6 pallets'!D18))/((1+$G$5)*(1+$F$5))) -> 0.32654072 | M14: =ROUNDDOWN((($H14/$D$5/(1+$C$5)-('Price 120 UAH - 6 pallets'!E16+'Price 120 UAH - 6 pallets'!F16+'Price 120 UAH - 6 pallets'!G16+'Price 120 UAH - 6 pallets'!E16*'Price 120 UAH - 6 pallets'!B18*($G$5+$F$5*(1+$G$5)))/('Price 120 UAH - 6 pallets'!C18*'Price 120 UAH - 6 pallets'!D18))/((1+$G$5)*(1+$F$5))),2) -> 0.32 | N14: =M14/0.65-1 -> -0.50769231
A15: EXAMPLE: +10 % proportional uplift of landed cost (the request gets lower)
A16: Bonus 25 % + margin 20 % + 10 % uplift | B16: 0.25 | C16: 0.2 | D16: 0.1 | E16: =$E$5*B16 -> 21.428571 | F16: =$E$5*C16 -> 17.142857 | G16: =$E$5-E16-F16 -> 47.142857 | H16: =G16/(1+D16) -> 42.857143 | I16: =(($H16/$D$5/(1+$C$5)-('Price 120 UAH - 33 pallets'!E16+'Price 120 UAH - 33 pallets'!F16+'Price 120 UAH - 33 pallets'!G16+'Price 120 UAH - 33 pallets'!E16*'Price 120 UAH - 33 pallets'!B18*($G$5+$F$5*(1+$G$5)))/('Price 120 UAH - 33 pallets'!C18*'Price 120 UAH - 33 pallets'!D18))/((1+$G$5)*(1+$F$5))) -> 0.60875106 | J16: =ROUNDDOWN((($H16/$D$5/(1+$C$5)-('Price 120 UAH - 33 pallets'!E16+'Price 120 UAH - 33 pallets'!F16+'Price 120 UAH - 33 pallets'!G16+'Price 120 UAH - 33 pallets'!E16*'Price 120 UAH - 33 pallets'!B18*($G$5+$F$5*(1+$G$5)))/('Price 120 UAH - 33 pallets'!C18*'Price 120 UAH - 33 pallets'!D18))/((1+$G$5)*(1+$F$5))),2) -> 0.6 | K16: =J16/0.65-1 -> -0.076923077 | L16: =(($H16/$D$5/(1+$C$5)-('Price 120 UAH - 6 pallets'!E16+'Price 120 UAH - 6 pallets'!F16+'Price 120 UAH - 6 pallets'!G16+'Price 120 UAH - 6 pallets'!E16*'Price 120 UAH - 6 pallets'!B18*($G$5+$F$5*(1+$G$5)))/('Price 120 UAH - 6 pallets'!C18*'Price 120 UAH - 6 pallets'!D18))/((1+$G$5)*(1+$F$5))) -> 0.39459386 | M16: =ROUNDDOWN((($H16/$D$5/(1+$C$5)-('Price 120 UAH - 6 pallets'!E16+'Price 120 UAH - 6 pallets'!F16+'Price 120 UAH - 6 pallets'!G16+'Price 120 UAH - 6 pallets'!E16*'Price 120 UAH - 6 pallets'!B18*($G$5+$F$5*(1+$G$5)))/('Price 120 UAH - 6 pallets'!C18*'Price 120 UAH - 6 pallets'!D18))/((1+$G$5)*(1+$F$5))),2) -> 0.39 | N16: =M16/0.65-1 -> -0.4
A17: Bonus 25 % + margin 25 % + 10 % uplift | B17: 0.25 | C17: 0.25 | D17: 0.1 | E17: =$E$5*B17 -> 21.428571 | F17: =$E$5*C17 -> 21.428571 | G17: =$E$5-E17-F17 -> 42.857143 | H17: =G17/(1+D17) -> 38.961039 | I17: =(($H17/$D$5/(1+$C$5)-('Price 120 UAH - 33 pallets'!E16+'Price 120 UAH - 33 pallets'!F16+'Price 120 UAH - 33 pallets'!G16+'Price 120 UAH - 33 pallets'!E16*'Price 120 UAH - 33 pallets'!B18*($G$5+$F$5*(1+$G$5)))/('Price 120 UAH - 33 pallets'!C18*'Price 120 UAH - 33 pallets'!D18))/((1+$G$5)*(1+$F$5))) -> 0.54688457 | J17: =ROUNDDOWN((($H17/$D$5/(1+$C$5)-('Price 120 UAH - 33 pallets'!E16+'Price 120 UAH - 33 pallets'!F16+'Price 120 UAH - 33 pallets'!G16+'Price 120 UAH - 33 pallets'!E16*'Price 120 UAH - 33 pallets'!B18*($G$5+$F$5*(1+$G$5)))/('Price 120 UAH - 33 pallets'!C18*'Price 120 UAH - 33 pallets'!D18))/((1+$G$5)*(1+$F$5))),2) -> 0.54 | K17: =J17/0.65-1 -> -0.16923077 | L17: =(($H17/$D$5/(1+$C$5)-('Price 120 UAH - 6 pallets'!E16+'Price 120 UAH - 6 pallets'!F16+'Price 120 UAH - 6 pallets'!G16+'Price 120 UAH - 6 pallets'!E16*'Price 120 UAH - 6 pallets'!B18*($G$5+$F$5*(1+$G$5)))/('Price 120 UAH - 6 pallets'!C18*'Price 120 UAH - 6 pallets'!D18))/((1+$G$5)*(1+$F$5))) -> 0.33272737 | M17: =ROUNDDOWN((($H17/$D$5/(1+$C$5)-('Price 120 UAH - 6 pallets'!E16+'Price 120 UAH - 6 pallets'!F16+'Price 120 UAH - 6 pallets'!G16+'Price 120 UAH - 6 pallets'!E16*'Price 120 UAH - 6 pallets'!B18*($G$5+$F$5*(1+$G$5)))/('Price 120 UAH - 6 pallets'!C18*'Price 120 UAH - 6 pallets'!D18))/((1+$G$5)*(1+$F$5))),2) -> 0.33 | N17: =M17/0.65-1 -> -0.49230769
A18: Bonus 35 % + margin 20 % + 10 % uplift | B18: 0.35 | C18: 0.2 | D18: 0.1 | E18: =$E$5*B18 -> 30 | F18: =$E$5*C18 -> 17.142857 | G18: =$E$5-E18-F18 -> 38.571429 | H18: =G18/(1+D18) -> 35.064935 | I18: =(($H18/$D$5/(1+$C$5)-('Price 120 UAH - 33 pallets'!E16+'Price 120 UAH - 33 pallets'!F16+'Price 120 UAH - 33 pallets'!G16+'Price 120 UAH - 33 pallets'!E16*'Price 120 UAH - 33 pallets'!B18*($G$5+$F$5*(1+$G$5)))/('Price 120 UAH - 33 pallets'!C18*'Price 120 UAH - 33 pallets'!D18))/((1+$G$5)*(1+$F$5))) -> 0.48501808 | J18: =ROUNDDOWN((($H18/$D$5/(1+$C$5)-('Price 120 UAH - 33 pallets'!E16+'Price 120 UAH - 33 pallets'!F16+'Price 120 UAH - 33 pallets'!G16+'Price 120 UAH - 33 pallets'!E16*'Price 120 UAH - 33 pallets'!B18*($G$5+$F$5*(1+$G$5)))/('Price 120 UAH - 33 pallets'!C18*'Price 120 UAH - 33 pallets'!D18))/((1+$G$5)*(1+$F$5))),2) -> 0.48 | K18: =J18/0.65-1 -> -0.26153846 | L18: =(($H18/$D$5/(1+$C$5)-('Price 120 UAH - 6 pallets'!E16+'Price 120 UAH - 6 pallets'!F16+'Price 120 UAH - 6 pallets'!G16+'Price 120 UAH - 6 pallets'!E16*'Price 120 UAH - 6 pallets'!B18*($G$5+$F$5*(1+$G$5)))/('Price 120 UAH - 6 pallets'!C18*'Price 120 UAH - 6 pallets'!D18))/((1+$G$5)*(1+$F$5))) -> 0.27086088 | M18: =ROUNDDOWN((($H18/$D$5/(1+$C$5)-('Price 120 UAH - 6 pallets'!E16+'Price 120 UAH - 6 pallets'!F16+'Price 120 UAH - 6 pallets'!G16+'Price 120 UAH - 6 pallets'!E16*'Price 120 UAH - 6 pallets'!B18*($G$5+$F$5*(1+$G$5)))/('Price 120 UAH - 6 pallets'!C18*'Price 120 UAH - 6 pallets'!D18))/((1+$G$5)*(1+$F$5))),2) -> 0.27 | N18: =M18/0.65-1 -> -0.58461538
A19: Bonus 35 % + margin 25 % + 10 % uplift | B19: 0.35 | C19: 0.25 | D19: 0.1 | E19: =$E$5*B19 -> 30 | F19: =$E$5*C19 -> 21.428571 | G19: =$E$5-E19-F19 -> 34.285714 | H19: =G19/(1+D19) -> 31.168831 | I19: =(($H19/$D$5/(1+$C$5)-('Price 120 UAH - 33 pallets'!E16+'Price 120 UAH - 33 pallets'!F16+'Price 120 UAH - 33 pallets'!G16+'Price 120 UAH - 33 pallets'!E16*'Price 120 UAH - 33 pallets'!B18*($G$5+$F$5*(1+$G$5)))/('Price 120 UAH - 33 pallets'!C18*'Price 120 UAH - 33 pallets'!D18))/((1+$G$5)*(1+$F$5))) -> 0.42315159 | J19: =ROUNDDOWN((($H19/$D$5/(1+$C$5)-('Price 120 UAH - 33 pallets'!E16+'Price 120 UAH - 33 pallets'!F16+'Price 120 UAH - 33 pallets'!G16+'Price 120 UAH - 33 pallets'!E16*'Price 120 UAH - 33 pallets'!B18*($G$5+$F$5*(1+$G$5)))/('Price 120 UAH - 33 pallets'!C18*'Price 120 UAH - 33 pallets'!D18))/((1+$G$5)*(1+$F$5))),2) -> 0.42 | K19: =J19/0.65-1 -> -0.35384615 | L19: =(($H19/$D$5/(1+$C$5)-('Price 120 UAH - 6 pallets'!E16+'Price 120 UAH - 6 pallets'!F16+'Price 120 UAH - 6 pallets'!G16+'Price 120 UAH - 6 pallets'!E16*'Price 120 UAH - 6 pallets'!B18*($G$5+$F$5*(1+$G$5)))/('Price 120 UAH - 6 pallets'!C18*'Price 120 UAH - 6 pallets'!D18))/((1+$G$5)*(1+$F$5))) -> 0.2089944 | M19: =ROUNDDOWN((($H19/$D$5/(1+$C$5)-('Price 120 UAH - 6 pallets'!E16+'Price 120 UAH - 6 pallets'!F16+'Price 120 UAH - 6 pallets'!G16+'Price 120 UAH - 6 pallets'!E16*'Price 120 UAH - 6 pallets'!B18*($G$5+$F$5*(1+$G$5)))/('Price 120 UAH - 6 pallets'!C18*'Price 120 UAH - 6 pallets'!D18))/((1+$G$5)*(1+$F$5))),2) -> 0.2 | N19: =M19/0.65-1 -> -0.69230769
A20: CHAIN BONUS 35 %: if the margin must stay above 20 %, the request falls
A21: Bonus 35 % + margin 25 % (no uplift) | B21: 0.35 | C21: 0.25 | D21: 0 | E21: =$E$5*B21 -> 30 | F21: =$E$5*C21 -> 21.428571 | G21: =$E$5-E21-F21 -> 34.285714 | H21: =G21/(1+D21) -> 34.285714 | I21: =(($H21/$D$5/(1+$C$5)-('Price 120 UAH - 33 pallets'!E16+'Price 120 UAH - 33 pallets'!F16+'Price 120 UAH - 33 pallets'!G16+'Price 120 UAH - 33 pallets'!E16*'Price 120 UAH - 33 pallets'!B18*($G$5+$F$5*(1+$G$5)))/('Price 120 UAH - 33 pallets'!C18*'Price 120 UAH - 33 pallets'!D18))/((1+$G$5)*(1+$F$5))) -> 0.47264478 | J21: =ROUNDDOWN((($H21/$D$5/(1+$C$5)-('Price 120 UAH - 33 pallets'!E16+'Price 120 UAH - 33 pallets'!F16+'Price 120 UAH - 33 pallets'!G16+'Price 120 UAH - 33 pallets'!E16*'Price 120 UAH - 33 pallets'!B18*($G$5+$F$5*(1+$G$5)))/('Price 120 UAH - 33 pallets'!C18*'Price 120 UAH - 33 pallets'!D18))/((1+$G$5)*(1+$F$5))),2) -> 0.47 | K21: =J21/0.65-1 -> -0.27692308 | L21: =(($H21/$D$5/(1+$C$5)-('Price 120 UAH - 6 pallets'!E16+'Price 120 UAH - 6 pallets'!F16+'Price 120 UAH - 6 pallets'!G16+'Price 120 UAH - 6 pallets'!E16*'Price 120 UAH - 6 pallets'!B18*($G$5+$F$5*(1+$G$5)))/('Price 120 UAH - 6 pallets'!C18*'Price 120 UAH - 6 pallets'!D18))/((1+$G$5)*(1+$F$5))) -> 0.25848759 | M21: =ROUNDDOWN((($H21/$D$5/(1+$C$5)-('Price 120 UAH - 6 pallets'!E16+'Price 120 UAH - 6 pallets'!F16+'Price 120 UAH - 6 pallets'!G16+'Price 120 UAH - 6 pallets'!E16*'Price 120 UAH - 6 pallets'!B18*($G$5+$F$5*(1+$G$5)))/('Price 120 UAH - 6 pallets'!C18*'Price 120 UAH - 6 pallets'!D18))/((1+$G$5)*(1+$F$5))),2) -> 0.25 | N21: =M21/0.65-1 -> -0.61538462
A22: Bonus 35 % + margin 30 % (no uplift) | B22: 0.35 | C22: 0.3 | D22: 0 | E22: =$E$5*B22 -> 30 | F22: =$E$5*C22 -> 25.714286 | G22: =$E$5-E22-F22 -> 30 | H22: =G22/(1+D22) -> 30 | I22: =(($H22/$D$5/(1+$C$5)-('Price 120 UAH - 33 pallets'!E16+'Price 120 UAH - 33 pallets'!F16+'Price 120 UAH - 33 pallets'!G16+'Price 120 UAH - 33 pallets'!E16*'Price 120 UAH - 33 pallets'!B18*($G$5+$F$5*(1+$G$5)))/('Price 120 UAH - 33 pallets'!C18*'Price 120 UAH - 33 pallets'!D18))/((1+$G$5)*(1+$F$5))) -> 0.40459165 | J22: =ROUNDDOWN((($H22/$D$5/(1+$C$5)-('Price 120 UAH - 33 pallets'!E16+'Price 120 UAH - 33 pallets'!F16+'Price 120 UAH - 33 pallets'!G16+'Price 120 UAH - 33 pallets'!E16*'Price 120 UAH - 33 pallets'!B18*($G$5+$F$5*(1+$G$5)))/('Price 120 UAH - 33 pallets'!C18*'Price 120 UAH - 33 pallets'!D18))/((1+$G$5)*(1+$F$5))),2) -> 0.4 | K22: =J22/0.65-1 -> -0.38461538 | L22: =(($H22/$D$5/(1+$C$5)-('Price 120 UAH - 6 pallets'!E16+'Price 120 UAH - 6 pallets'!F16+'Price 120 UAH - 6 pallets'!G16+'Price 120 UAH - 6 pallets'!E16*'Price 120 UAH - 6 pallets'!B18*($G$5+$F$5*(1+$G$5)))/('Price 120 UAH - 6 pallets'!C18*'Price 120 UAH - 6 pallets'!D18))/((1+$G$5)*(1+$F$5))) -> 0.19043445 | M22: =ROUNDDOWN((($H22/$D$5/(1+$C$5)-('Price 120 UAH - 6 pallets'!E16+'Price 120 UAH - 6 pallets'!F16+'Price 120 UAH - 6 pallets'!G16+'Price 120 UAH - 6 pallets'!E16*'Price 120 UAH - 6 pallets'!B18*($G$5+$F$5*(1+$G$5)))/('Price 120 UAH - 6 pallets'!C18*'Price 120 UAH - 6 pallets'!D18))/((1+$G$5)*(1+$F$5))),2) -> 0.19 | N22: =M22/0.65-1 -> -0.70769231
A23: ONLY THE MARGIN LOWERED (bonus 25 %, no extra cost): the allowed purchase price rises — the argument toward SIAS weakens
